INFO:     Will watch for changes in these directories: ['/Users/oscar/projects/CrawloDeployer/backend']
INFO:     Uvicorn running on http://0.0.0.0:8000 (Press CTRL+C to quit)
INFO:     Started reloader process [62714] using StatReload
[32m2025-09-14 21:06:38.532[0m | [1mINFO    [0m | [36mapp.core.logging_config[0m:[36msetup_logging[0m:[36m38[0m - [1mLogger setup complete.[0m
INFO:     Started server process [62765]
INFO:     Waiting for application startup.
[32m2025-09-14 21:06:38.548[0m | [1mINFO    [0m | [36mapp.core.lifespan[0m:[36mlifespan[0m:[36m13[0m - [1müöÄ CrawloDeployer Ê≠£Âú®ÂêØÂä®...[0m
[32m2025-09-14 21:06:38.552[0m | [1mINFO    [0m | [36mapp.core.lifespan[0m:[36mlifespan[0m:[36m26[0m - [1m‚úÖ Êï∞ÊçÆÂ∫ìËøûÊé•Ê≠£Â∏∏[0m
[32m2025-09-14 21:06:38.565[0m | [1mINFO    [0m | [36mapp.core.lifespan[0m:[36mlifespan[0m:[36m34[0m - [1m‚úÖ ÂÆöÊó∂‰ªªÂä°Ë∞ÉÂ∫¶Âô®Â∑≤ÂêØÂä®[0m
INFO:     Application startup complete.
(trapped) error reading bcrypt version
Traceback (most recent call last):
  File "/Users/oscar/software/miniconda3/envs/crawl_pro/lib/python3.12/site-packages/passlib/handlers/bcrypt.py", line 620, in _load_backend_mixin
    version = _bcrypt.__about__.__version__
              ^^^^^^^^^^^^^^^^^
AttributeError: module 'bcrypt' has no attribute '__about__'
INFO:     127.0.0.1:55334 - "POST /api/v1/auth/login HTTP/1.1" 401 Unauthorized
INFO:     127.0.0.1:55402 - "POST /api/v1/auth/login HTTP/1.1" 200 OK
INFO:     127.0.0.1:55426 - "POST /api/v1/auth/login HTTP/1.1" 200 OK
INFO:     127.0.0.1:55458 - "POST /api/v1/auth/login HTTP/1.1" 200 OK
INFO:     127.0.0.1:55460 - "POST /api/v1/git-credentials/ HTTP/1.1" 422 Unprocessable Entity
INFO:     127.0.0.1:55490 - "POST /api/v1/auth/login HTTP/1.1" 200 OK
INFO:     127.0.0.1:55492 - "POST /api/v1/git-credentials/ HTTP/1.1" 500 Internal Server Error
ERROR:    Exception in ASGI application
Traceback (most recent call last):
  File "/Users/oscar/software/miniconda3/envs/crawl_pro/lib/python3.12/site-packages/sqlalchemy/engine/base.py", line 1961, in _exec_single_context
    self.dialect.do_execute(
  File "/Users/oscar/software/miniconda3/envs/crawl_pro/lib/python3.12/site-packages/sqlalchemy/engine/default.py", line 944, in do_execute
    cursor.execute(statement, parameters)
  File "/Users/oscar/software/miniconda3/envs/crawl_pro/lib/python3.12/site-packages/pymysql/cursors.py", line 153, in execute
    result = self._query(query)
             ^^^^^^^^^^^^^^^^^^
  File "/Users/oscar/software/miniconda3/envs/crawl_pro/lib/python3.12/site-packages/pymysql/cursors.py", line 322, in _query
    conn.query(q)
  File "/Users/oscar/software/miniconda3/envs/crawl_pro/lib/python3.12/site-packages/pymysql/connections.py", line 563, in query
    self._affected_rows = self._read_query_result(unbuffered=unbuffered)
                          ^^^^^^^^^^^^^^^^^^^^^^^^^^^^^^^^^^^^^^^^^^^^^^
  File "/Users/oscar/software/miniconda3/envs/crawl_pro/lib/python3.12/site-packages/pymysql/connections.py", line 825, in _read_query_result
    result.read()
  File "/Users/oscar/software/miniconda3/envs/crawl_pro/lib/python3.12/site-packages/pymysql/connections.py", line 1199, in read
    first_packet = self.connection._read_packet()
                   ^^^^^^^^^^^^^^^^^^^^^^^^^^^^^^
  File "/Users/oscar/software/miniconda3/envs/crawl_pro/lib/python3.12/site-packages/pymysql/connections.py", line 775, in _read_packet
    packet.raise_for_error()
  File "/Users/oscar/software/miniconda3/envs/crawl_pro/lib/python3.12/site-packages/pymysql/protocol.py", line 219, in raise_for_error
    err.raise_mysql_exception(self._data)
  File "/Users/oscar/software/miniconda3/envs/crawl_pro/lib/python3.12/site-packages/pymysql/err.py", line 150, in raise_mysql_exception
    raise errorclass(errno, errval)
pymysql.err.IntegrityError: (1048, "Column 'encrypted_token' cannot be null")

The above exception was the direct cause of the following exception:

Traceback (most recent call last):
  File "/Users/oscar/software/miniconda3/envs/crawl_pro/lib/python3.12/site-packages/uvicorn/protocols/http/h11_impl.py", line 403, in run_asgi
    result = await app(  # type: ignore[func-returns-value]
             ^^^^^^^^^^^^^^^^^^^^^^^^^^^^^^^^^^^^^^^^^^^^^^
  File "/Users/oscar/software/miniconda3/envs/crawl_pro/lib/python3.12/site-packages/uvicorn/middleware/proxy_headers.py", line 60, in __call__
    return await self.app(scope, receive, send)
           ^^^^^^^^^^^^^^^^^^^^^^^^^^^^^^^^^^^^
  File "/Users/oscar/software/miniconda3/envs/crawl_pro/lib/python3.12/site-packages/fastapi/applications.py", line 1054, in __call__
    await super().__call__(scope, receive, send)
  File "/Users/oscar/software/miniconda3/envs/crawl_pro/lib/python3.12/site-packages/starlette/applications.py", line 113, in __call__
    await self.middleware_stack(scope, receive, send)
  File "/Users/oscar/software/miniconda3/envs/crawl_pro/lib/python3.12/site-packages/starlette/middleware/errors.py", line 186, in __call__
    raise exc
  File "/Users/oscar/software/miniconda3/envs/crawl_pro/lib/python3.12/site-packages/starlette/middleware/errors.py", line 164, in __call__
    await self.app(scope, receive, _send)
  File "/Users/oscar/software/miniconda3/envs/crawl_pro/lib/python3.12/site-packages/starlette/middleware/cors.py", line 85, in __call__
    await self.app(scope, receive, send)
  File "/Users/oscar/software/miniconda3/envs/crawl_pro/lib/python3.12/site-packages/starlette/middleware/exceptions.py", line 63, in __call__
    await wrap_app_handling_exceptions(self.app, conn)(scope, receive, send)
  File "/Users/oscar/software/miniconda3/envs/crawl_pro/lib/python3.12/site-packages/starlette/_exception_handler.py", line 53, in wrapped_app
    raise exc
  File "/Users/oscar/software/miniconda3/envs/crawl_pro/lib/python3.12/site-packages/starlette/_exception_handler.py", line 42, in wrapped_app
    await app(scope, receive, sender)
  File "/Users/oscar/software/miniconda3/envs/crawl_pro/lib/python3.12/site-packages/starlette/routing.py", line 716, in __call__
    await self.middleware_stack(scope, receive, send)
  File "/Users/oscar/software/miniconda3/envs/crawl_pro/lib/python3.12/site-packages/starlette/routing.py", line 736, in app
    await route.handle(scope, receive, send)
  File "/Users/oscar/software/miniconda3/envs/crawl_pro/lib/python3.12/site-packages/starlette/routing.py", line 290, in handle
    await self.app(scope, receive, send)
  File "/Users/oscar/software/miniconda3/envs/crawl_pro/lib/python3.12/site-packages/starlette/routing.py", line 78, in app
    await wrap_app_handling_exceptions(app, request)(scope, receive, send)
  File "/Users/oscar/software/miniconda3/envs/crawl_pro/lib/python3.12/site-packages/starlette/_exception_handler.py", line 53, in wrapped_app
    raise exc
  File "/Users/oscar/software/miniconda3/envs/crawl_pro/lib/python3.12/site-packages/starlette/_exception_handler.py", line 42, in wrapped_app
    await app(scope, receive, sender)
  File "/Users/oscar/software/miniconda3/envs/crawl_pro/lib/python3.12/site-packages/starlette/routing.py", line 75, in app
    response = await f(request)
               ^^^^^^^^^^^^^^^^
  File "/Users/oscar/software/miniconda3/envs/crawl_pro/lib/python3.12/site-packages/fastapi/routing.py", line 302, in app
    raw_response = await run_endpoint_function(
                   ^^^^^^^^^^^^^^^^^^^^^^^^^^^^
  File "/Users/oscar/software/miniconda3/envs/crawl_pro/lib/python3.12/site-packages/fastapi/routing.py", line 215, in run_endpoint_function
    return await run_in_threadpool(dependant.call, **values)
           ^^^^^^^^^^^^^^^^^^^^^^^^^^^^^^^^^^^^^^^^^^^^^^^^^
  File "/Users/oscar/software/miniconda3/envs/crawl_pro/lib/python3.12/site-packages/starlette/concurrency.py", line 38, in run_in_threadpool
    return await anyio.to_thread.run_sync(func)
           ^^^^^^^^^^^^^^^^^^^^^^^^^^^^^^^^^^^^
  File "/Users/oscar/software/miniconda3/envs/crawl_pro/lib/python3.12/site-packages/anyio/to_thread.py", line 56, in run_sync
    return await get_async_backend().run_sync_in_worker_thread(
           ^^^^^^^^^^^^^^^^^^^^^^^^^^^^^^^^^^^^^^^^^^^^^^^^^^^^
  File "/Users/oscar/software/miniconda3/envs/crawl_pro/lib/python3.12/site-packages/anyio/_backends/_asyncio.py", line 2470, in run_sync_in_worker_thread
    return await future
           ^^^^^^^^^^^^
  File "/Users/oscar/software/miniconda3/envs/crawl_pro/lib/python3.12/site-packages/anyio/_backends/_asyncio.py", line 967, in run
    result = context.run(func, *args)
             ^^^^^^^^^^^^^^^^^^^^^^^^
  File "/Users/oscar/projects/CrawloDeployer/backend/app/api/v1/endpoints/git_credentials.py", line 32, in create_git_credential
    credential_in_db = crud_git_cred.create_with_owner(
                       ^^^^^^^^^^^^^^^^^^^^^^^^^^^^^^^^
  File "/Users/oscar/projects/CrawloDeployer/backend/app/crud/git_credential.py", line 48, in create_with_owner
    db.flush()
  File "/Users/oscar/software/miniconda3/envs/crawl_pro/lib/python3.12/site-packages/sqlalchemy/orm/session.py", line 4345, in flush
    self._flush(objects)
  File "/Users/oscar/software/miniconda3/envs/crawl_pro/lib/python3.12/site-packages/sqlalchemy/orm/session.py", line 4480, in _flush
    with util.safe_reraise():
         ^^^^^^^^^^^^^^^^^^^
  File "/Users/oscar/software/miniconda3/envs/crawl_pro/lib/python3.12/site-packages/sqlalchemy/util/langhelpers.py", line 224, in __exit__
    raise exc_value.with_traceback(exc_tb)
  File "/Users/oscar/software/miniconda3/envs/crawl_pro/lib/python3.12/site-packages/sqlalchemy/orm/session.py", line 4441, in _flush
    flush_context.execute()
  File "/Users/oscar/software/miniconda3/envs/crawl_pro/lib/python3.12/site-packages/sqlalchemy/orm/unitofwork.py", line 466, in execute
    rec.execute(self)
  File "/Users/oscar/software/miniconda3/envs/crawl_pro/lib/python3.12/site-packages/sqlalchemy/orm/unitofwork.py", line 642, in execute
    util.preloaded.orm_persistence.save_obj(
  File "/Users/oscar/software/miniconda3/envs/crawl_pro/lib/python3.12/site-packages/sqlalchemy/orm/persistence.py", line 93, in save_obj
    _emit_insert_statements(
  File "/Users/oscar/software/miniconda3/envs/crawl_pro/lib/python3.12/site-packages/sqlalchemy/orm/persistence.py", line 1233, in _emit_insert_statements
    result = connection.execute(
             ^^^^^^^^^^^^^^^^^^^
  File "/Users/oscar/software/miniconda3/envs/crawl_pro/lib/python3.12/site-packages/sqlalchemy/engine/base.py", line 1413, in execute
    return meth(
           ^^^^^
  File "/Users/oscar/software/miniconda3/envs/crawl_pro/lib/python3.12/site-packages/sqlalchemy/sql/elements.py", line 526, in _execute_on_connection
    return connection._execute_clauseelement(
           ^^^^^^^^^^^^^^^^^^^^^^^^^^^^^^^^^^
  File "/Users/oscar/software/miniconda3/envs/crawl_pro/lib/python3.12/site-packages/sqlalchemy/engine/base.py", line 1635, in _execute_clauseelement
    ret = self._execute_context(
          ^^^^^^^^^^^^^^^^^^^^^^
  File "/Users/oscar/software/miniconda3/envs/crawl_pro/lib/python3.12/site-packages/sqlalchemy/engine/base.py", line 1840, in _execute_context
    return self._exec_single_context(
           ^^^^^^^^^^^^^^^^^^^^^^^^^^
  File "/Users/oscar/software/miniconda3/envs/crawl_pro/lib/python3.12/site-packages/sqlalchemy/engine/base.py", line 1980, in _exec_single_context
    self._handle_dbapi_exception(
  File "/Users/oscar/software/miniconda3/envs/crawl_pro/lib/python3.12/site-packages/sqlalchemy/engine/base.py", line 2349, in _handle_dbapi_exception
    raise sqlalchemy_exception.with_traceback(exc_info[2]) from e
  File "/Users/oscar/software/miniconda3/envs/crawl_pro/lib/python3.12/site-packages/sqlalchemy/engine/base.py", line 1961, in _exec_single_context
    self.dialect.do_execute(
  File "/Users/oscar/software/miniconda3/envs/crawl_pro/lib/python3.12/site-packages/sqlalchemy/engine/default.py", line 944, in do_execute
    cursor.execute(statement, parameters)
  File "/Users/oscar/software/miniconda3/envs/crawl_pro/lib/python3.12/site-packages/pymysql/cursors.py", line 153, in execute
    result = self._query(query)
             ^^^^^^^^^^^^^^^^^^
  File "/Users/oscar/software/miniconda3/envs/crawl_pro/lib/python3.12/site-packages/pymysql/cursors.py", line 322, in _query
    conn.query(q)
  File "/Users/oscar/software/miniconda3/envs/crawl_pro/lib/python3.12/site-packages/pymysql/connections.py", line 563, in query
    self._affected_rows = self._read_query_result(unbuffered=unbuffered)
                          ^^^^^^^^^^^^^^^^^^^^^^^^^^^^^^^^^^^^^^^^^^^^^^
  File "/Users/oscar/software/miniconda3/envs/crawl_pro/lib/python3.12/site-packages/pymysql/connections.py", line 825, in _read_query_result
    result.read()
  File "/Users/oscar/software/miniconda3/envs/crawl_pro/lib/python3.12/site-packages/pymysql/connections.py", line 1199, in read
    first_packet = self.connection._read_packet()
                   ^^^^^^^^^^^^^^^^^^^^^^^^^^^^^^
  File "/Users/oscar/software/miniconda3/envs/crawl_pro/lib/python3.12/site-packages/pymysql/connections.py", line 775, in _read_packet
    packet.raise_for_error()
  File "/Users/oscar/software/miniconda3/envs/crawl_pro/lib/python3.12/site-packages/pymysql/protocol.py", line 219, in raise_for_error
    err.raise_mysql_exception(self._data)
  File "/Users/oscar/software/miniconda3/envs/crawl_pro/lib/python3.12/site-packages/pymysql/err.py", line 150, in raise_mysql_exception
    raise errorclass(errno, errval)
sqlalchemy.exc.IntegrityError: (pymysql.err.IntegrityError) (1048, "Column 'encrypted_token' cannot be null")
[SQL: INSERT INTO git_credentials (user_id, provider, username, encrypted_token, encrypted_ssh_key, ssh_key_fingerprint) VALUES (%(user_id)s, %(provider)s, %(username)s, %(encrypted_token)s, %(encrypted_ssh_key)s, %(ssh_key_fingerprint)s)]
[parameters: {'user_id': 36, 'provider': 'github', 'username': 'testuser', 'encrypted_token': None, 'encrypted_ssh_key': 'gAAAAABoxsGFBu7T_IWUlzGk7D1WrxbtDsMpV3IfdVE_l6ebSgqTSm-jbV6h7SbP4HG9HVlOc1EG4hH9ZGkg0cpoNRhFJTIPqw==', 'ssh_key_fingerprint': 'test-fingerprint'}]
(Background on this error at: https://sqlalche.me/e/20/gkpj)
WARNING:  StatReload detected changes in 'app/utils/git_utils.py'. Reloading...
INFO:     Shutting down
INFO:     Waiting for application shutdown.
[32m2025-09-14 21:24:33.388[0m | [1mINFO    [0m | [36mapp.core.lifespan[0m:[36mlifespan[0m:[36m42[0m - [1müõë CrawloDeployer Ê≠£Âú®ÂÖ≥Èó≠...[0m
[32m2025-09-14 21:24:33.388[0m | [1mINFO    [0m | [36mapp.core.lifespan[0m:[36mlifespan[0m:[36m45[0m - [1m‚úÖ Ë∞ÉÂ∫¶Âô®Â∑≤ÂÆâÂÖ®ÂÖ≥Èó≠[0m
[32m2025-09-14 21:24:33.389[0m | [1mINFO    [0m | [36mapp.core.lifespan[0m:[36mlifespan[0m:[36m51[0m - [1m‚úÖ Êï∞ÊçÆÂ∫ìÂºïÊìéÂ∑≤ÂÖ≥Èó≠[0m
INFO:     Application shutdown complete.
INFO:     Finished server process [62765]
Fatal Python error: init_sys_streams: can't initialize sys standard streams
Python runtime state: core initialized
OSError: [Errno 9] Bad file descriptor

Current thread 0x00000001f8bd60c0 (most recent call first):
  <no Python frame>
WARNING:  StatReload detected changes in 'app/api/v1/endpoints/projects.py'. Reloading...
Fatal Python error: init_sys_streams: can't initialize sys standard streams
Python runtime state: core initialized
OSError: [Errno 9] Bad file descriptor

Current thread 0x00000001f8bd60c0 (most recent call first):
  <no Python frame>
/Users/oscar/software/miniconda3/envs/crawl_pro/lib/python3.12/multiprocessing/resource_tracker.py:279: UserWarning: resource_tracker: There appear to be 8 leaked semaphore objects to clean up at shutdown
  warnings.warn('resource_tracker: There appear to be %d '
